Workbook

Sheet Summary
A1: Gratuity DBO: Summary of Results
A2: ILLUSTRATIVE MODEL USING SYNTHETIC DATA. Assumptions are placeholders; see the Assumptions sheet.
A4: Measure | B4: Value
A5: Number of employees | B5: =COUNTA(Census!$A$6:$A$155) -> 150
A6: Employees eligible today (service >= 5 years) | B6: =SUM(Census!$K$6:$K$155) -> 100
A7: Defined Benefit Obligation, DBO (Rs) | B7: =SUM(Census!$L$6:$L$155) -> 46785528
A8: Current service cost, next year (Rs) | B8: =SUM(Census!$M$6:$M$155) -> 3723248.4
A9: Interest cost, next year, approx. = discount rate x DBO (Rs) | B9: =Assumptions!$B$8*B7 -> 3274986.9
A10: Expected payments in year 1 for service earned to date (Rs) | B10: =B20 -> 3990406
A11: Weighted average term of the liability (years) | B11: =SUMPRODUCT(A20:A64,D20:D64)/SUM(D20:D64) -> 8.675623
A12: Benefit if all eligible employees left today (Rs) | B12: =SUMPRODUCT(Census!$J$6:$J$155,Census!$K$6:$K$155) -> 78425827
A13: DBO as % of that reference figure | B13: =B7/B12 -> 0.59655766
A14: Share of DBO held by the top 10 employees | B14: =SUMPRODUCT(LARGE(Census!$L$6:$L$155,{1,2,3,4,5,6,7,8,9,10}))/B7 -> 0.22813265
A16: Reconciliation: PV of cash flows below minus DBO (should be 0) | B16: =SUM(D20:D64)-B7 -> 0
A18: Expected payments for service earned to date, by future year
A19: Year from valuation date (t) | B19: Expected payments, undiscounted (Rs) | C19: Discount factor | D19: Present value (Rs)
A20: 1 | B20: =SUMPRODUCT(INDEX(Benefit_Grid!$C$6:$AU$155,0,A20)*Census!$F$6:$F$155/(Census!$F$6:$F$155+A20)) -> 3990406 | C20: =(1/(1+Assumptions!$B$8))^A20 -> 0.93457944 | D20: =B20*C20 -> 3729351.4
A21: =A20+1 -> 2 | B21: =SUMPRODUCT(INDEX(Benefit_Grid!$C$6:$AU$155,0,A21)*Census!$F$6:$F$155/(Census!$F$6:$F$155+A21)) -> 3726064.7 | C21: =(1/(1+Assumptions!$B$8))^A21 -> 0.87343873 | D21: =B21*C21 -> 3254489.2
A22: =A21+1 -> 3 | B22: =SUMPRODUCT(INDEX(Benefit_Grid!$C$6:$AU$155,0,A22)*Census!$F$6:$F$155/(Census!$F$6:$F$155+A22)) -> 3403823.1 | C22: =(1/(1+Assumptions!$B$8))^A22 -> 0.81629788 | D22: =B22*C22 -> 2778533.5
A23: =A22+1 -> 4 | B23: =SUMPRODUCT(INDEX(Benefit_Grid!$C$6:$AU$155,0,A23)*Census!$F$6:$F$155/(Census!$F$6:$F$155+A23)) -> 3094926.5 | C23: =(1/(1+Assumptions!$B$8))^A23 -> 0.76289521 | D23: =B23*C23 -> 2361104.6
A24: =A23+1 -> 5 | B24: =SUMPRODUCT(INDEX(Benefit_Grid!$C$6:$AU$155,0,A24)*Census!$F$6:$F$155/(Census!$F$6:$F$155+A24)) -> 7603910.9 | C24: =(1/(1+Assumptions!$B$8))^A24 -> 0.71298618 | D24: =B24*C24 -> 5421483.4
A25: =A24+1 -> 6 | B25: =SUMPRODUCT(INDEX(Benefit_Grid!$C$6:$AU$155,0,A25)*Census!$F$6:$F$155/(Census!$F$6:$F$155+A25)) -> 3998581.8 | C25: =(1/(1+Assumptions!$B$8))^A25 -> 0.66634222 | D25: =B25*C25 -> 2664423.9
A26: =A25+1 -> 7 | B26: =SUMPRODUCT(INDEX(Benefit_Grid!$C$6:$AU$155,0,A26)*Census!$F$6:$F$155/(Census!$F$6:$F$155+A26)) -> 6388681.3 | C26: =(1/(1+Assumptions!$B$8))^A26 -> 0.62274974 | D26: =B26*C26 -> 3978549.6
A27: =A26+1 -> 8 | B27: =SUMPRODUCT(INDEX(Benefit_Grid!$C$6:$AU$155,0,A27)*Census!$F$6:$F$155/(Census!$F$6:$F$155+A27)) -> 4737826.8 | C27: =(1/(1+Assumptions!$B$8))^A27 -> 0.5820091 | D27: =B27*C27 -> 2757458.3
A28: =A27+1 -> 9 | B28: =SUMPRODUCT(INDEX(Benefit_Grid!$C$6:$AU$155,0,A28)*Census!$F$6:$F$155/(Census!$F$6:$F$155+A28)) -> 2915160.1 | C28: =(1/(1+Assumptions!$B$8))^A28 -> 0.54393374 | D28: =B28*C28 -> 1585654
A29: =A28+1 -> 10 | B29: =SUMPRODUCT(INDEX(Benefit_Grid!$C$6:$AU$155,0,A29)*Census!$F$6:$F$155/(Census!$F$6:$F$155+A29)) -> 4904407.7 | C29: =(1/(1+Assumptions!$B$8))^A29 -> 0.50834929 | D29: =B29*C29 -> 2493152.2
A30: =A29+1 -> 11 | B30: =SUMPRODUCT(INDEX(Benefit_Grid!$C$6:$AU$155,0,A30)*Census!$F$6:$F$155/(Census!$F$6:$F$155+A30)) -> 6515531.9 | C30: =(1/(1+Assumptions!$B$8))^A30 -> 0.4750928 | D30: =B30*C30 -> 3095482.3
A31: =A30+1 -> 12 | B31: =SUMPRODUCT(INDEX(Benefit_Grid!$C$6:$AU$155,0,A31)*Census!$F$6:$F$155/(Census!$F$6:$F$155+A31)) -> 4847983.4 | C31: =(1/(1+Assumptions!$B$8))^A31 -> 0.44401196 | D31: =B31*C31 -> 2152562.6
A32: =A31+1 -> 13 | B32: =SUMPRODUCT(INDEX(Benefit_Grid!$C$6:$AU$155,0,A32)*Census!$F$6:$F$155/(Census!$F$6:$F$155+A32)) -> 4521481.3 | C32: =(1/(1+Assumptions!$B$8))^A32 -> 0.41496445 | D32: =B32*C32 -> 1876254
... A64: =A63+1 -> 45 | B64: =SUMPRODUCT(INDEX(Benefit_Grid!$C$6:$AU$155,0,A64)*Census!$F$6:$F$155/(Census!$F$6:$F$155+A64)) -> 0 | C64: =(1/(1+Assumptions!$B$8))^A64 -> 0.047613489 | D64: =B64*C64 -> 0

Sheet Assumptions
A1: Gratuity Valuation (Projected Unit Credit): Assumptions
A2: ILLUSTRATIVE MODEL USING SYNTHETIC DATA. Not a real valuation.
A3: Legend: blue text = input you may edit; black = formula; yellow fill = key assumption.
A5: Assumption | B5: Value | C5: Basis / note
A6: Valuation date | B6: 46112 | C6: A financial year-end (chosen by the project).
A7: Retirement age (years) | B7: 60 | C7: Common assumption; the Stage 1 data check also uses 60.
A8: Discount rate | B8: 0.07 | C8: Proxy: 10-year government bond yield near 31 March 2026 (about 7.00% per a Trading Economics table; approximate, cite your source).
A9: Salary escalation (per year) | B9: 0.08 | C9: Illustrative judgement; in a real valuation it follows the employer's pay policy.
A10: Ceiling on gratuity (Rs) | B10: 2000000 | C10: Rs 20 lakh. Verify against the current notification.
A11: Minimum service for withdrawal benefit (years) | B11: 5 | C11: Five-year rule for exits other than death (and retirement here).
A12: Mortality A (Gompertz-Makeham) | B12: 0.0004 | C12: ILLUSTRATIVE placeholder; replace with the published IALM table.
A13: Mortality B | B13: 2e-05 | C13: ILLUSTRATIVE placeholder.
A14: Mortality c | B14: 1.1 | C14: ILLUSTRATIVE placeholder.
A17: Illustrative annual withdrawal rates by age band
A18: From age | B18: To age (exclusive) | C18: Annual withdrawal rate
A19: 18 | B19: 25 | C19: 0.2
A20: 25 | B20: 30 | C20: 0.15
A21: 30 | B21: 35 | C21: 0.11
A22: 35 | B22: 40 | C22: 0.08
A23: 40 | B23: 45 | C23: 0.05
A24: 45 | B24: 50 | C24: 0.03
A25: 50 | B25: 55 | C25: 0.02
A26: 55 | B26: 60 | C26: 0.01
A27: 60 | B27: 200 | C27: 0
A29: Rates are illustrative placeholders, not company or industry data.

Sheet Census
A1: Employee census and per-employee valuation
A2: SYNTHETIC DATA generated for learning (seed 2026). Columns A-D are inputs; E-M are formulas; N is the Python result pasted for cross-checking.
A3: DBO = sum over exit years of [expected benefit x service now / service at exit x discount factor]. See Benefit_Grid for the expected benefit by year.
A5: Emp ID | B5: Date of birth | C5: Date of joining | D5: Monthly wages (Rs) | E5: Age at valuation | F5: Service at valuation (years) | G5: Start age (rounded down) | H5: Years to retirement | I5: Years for formula (part-year rule) | J5: Benefit if exit today (Rs) | K5: Eligible today (1 = yes) | L5: DBO (Rs) | M5: Current service cost (Rs) | N5: Python DBO (Rs) | O5: Excel minus Python (Rs)
A6: E001 | B6: 35146 | C6: 44914 | D6: 23700 | E6: =(Assumptions!$B$6-B6)/365.25 -> 30.023272 | F6: =(Assumptions!$B$6-C6)/365.25 -> 3.2799452 | G6: =INT(E6) -> 30 | H6: =Assumptions!$B$7-G6 -> 30 | I6: =INT(F6)+IF(F6-INT(F6)>0.5,1,0) -> 3 | J6: =MIN(15/26*D6*I6,Assumptions!$B$10) -> 41019.231 | K6: =IF(F6>=Assumptions!$B$11,1,0) -> 0 | L6: =SUMPRODUCT(Benefit_Grid!$C6:$AU6*(F6/(F6+Benefit_Grid!$C$5:$AU$5))*(1/(1+Assumptions!$B$8))^Benefit_Grid!$C$5:$AU$5) -> 37093.242 | M6: =SUMPRODUCT(Benefit_Grid!$C6:$AU6/(F6+Benefit_Grid!$C$5:$AU$5)*(1/(1+Assumptions!$B$8))^Benefit_Grid!$C$5:$AU$5) -> 11309.104 | N6: 37093.242 | O6: =L6-N6 -> 3.4830009e-07
A7: E002 | B7: 33903 | C7: 45147 | D7: 33500 | E7: =(Assumptions!$B$6-B7)/365.25 -> 33.42642 | F7: =(Assumptions!$B$6-C7)/365.25 -> 2.642026 | G7: =INT(E7) -> 33 | H7: =Assumptions!$B$7-G7 -> 27 | I7: =INT(F7)+IF(F7-INT(F7)>0.5,1,0) -> 3 | J7: =MIN(15/26*D7*I7,Assumptions!$B$10) -> 57980.769 | K7: =IF(F7>=Assumptions!$B$11,1,0) -> 0 | L7: =SUMPRODUCT(Benefit_Grid!$C7:$AU7*(F7/(F7+Benefit_Grid!$C$5:$AU$5))*(1/(1+Assumptions!$B$8))^Benefit_Grid!$C$5:$AU$5) -> 36812.585 | M7: =SUMPRODUCT(Benefit_Grid!$C7:$AU7/(F7+Benefit_Grid!$C$5:$AU$5)*(1/(1+Assumptions!$B$8))^Benefit_Grid!$C$5:$AU$5) -> 13933.468 | N7: 36812.585 | O7: =L7-N7 -> 3.4522236e-07
A8: E003 | B8: 31513 | C8: 41035 | D8: 99400 | E8: =(Assumptions!$B$6-B8)/365.25 -> 39.969884 | F8: =(Assumptions!$B$6-C8)/365.25 -> 13.900068 | G8: =INT(E8) -> 39 | H8: =Assumptions!$B$7-G8 -> 21 | I8: =INT(F8)+IF(F8-INT(F8)>0.5,1,0) -> 14 | J8: =MIN(15/26*D8*I8,Assumptions!$B$10) -> 802846.15 | K8: =IF(F8>=Assumptions!$B$11,1,0) -> 1 | L8: =SUMPRODUCT(Benefit_Grid!$C8:$AU8*(F8/(F8+Benefit_Grid!$C$5:$AU$5))*(1/(1+Assumptions!$B$8))^Benefit_Grid!$C$5:$AU$5) -> 445115.16 | M8: =SUMPRODUCT(Benefit_Grid!$C8:$AU8/(F8+Benefit_Grid!$C$5:$AU$5)*(1/(1+Assumptions!$B$8))^Benefit_Grid!$C$5:$AU$5) -> 32022.516 | N8: 445115.16 | O8: =L8-N8 -> 1.1554221e-07
A9: E004 | B9: 31671 | C9: 44015 | D9: 44200 | E9: =(Assumptions!$B$6-B9)/365.25 -> 39.537303 | F9: =(Assumptions!$B$6-C9)/365.25 -> 5.7412731 | G9: =INT(E9) -> 39 | H9: =Assumptions!$B$7-G9 -> 21 | I9: =INT(F9)+IF(F9-INT(F9)>0.5,1,0) -> 6 | J9: =MIN(15/26*D9*I9,Assumptions!$B$10) -> 153000 | K9: =IF(F9>=Assumptions!$B$11,1,0) -> 1 | L9: =SUMPRODUCT(Benefit_Grid!$C9:$AU9*(F9/(F9+Benefit_Grid!$C$5:$AU$5))*(1/(1+Assumptions!$B$8))^Benefit_Grid!$C$5:$AU$5) -> 130464.78 | M9: =SUMPRODUCT(Benefit_Grid!$C9:$AU9/(F9+Benefit_Grid!$C$5:$AU$5)*(1/(1+Assumptions!$B$8))^Benefit_Grid!$C$5:$AU$5) -> 22724.016 | N9: 130464.78 | O9: =L9-N9 -> 2.6584894e-07
A10: E005 | B10: 33227 | C10: 42657 | D10: 49000 | E10: =(Assumptions!$B$6-B10)/365.25 -> 35.277207 | F10: =(Assumptions!$B$6-C10)/365.25 -> 9.4592745 | G10: =INT(E10) -> 35 | H10: =Assumptions!$B$7-G10 -> 25 | I10: =INT(F10)+IF(F10-INT(F10)>0.5,1,0) -> 9 | J10: =MIN(15/26*D10*I10,Assumptions!$B$10) -> 254423.08 | K10: =IF(F10>=Assumptions!$B$11,1,0) -> 1 | L10: =SUMPRODUCT(Benefit_Grid!$C10:$AU10*(F10/(F10+Benefit_Grid!$C$5:$AU$5))*(1/(1+Assumptions!$B$8))^Benefit_Grid!$C$5:$AU$5) -> 204697.4 | M10: =SUMPRODUCT(Benefit_Grid!$C10:$AU10/(F10+Benefit_Grid!$C$5:$AU$5)*(1/(1+Assumptions!$B$8))^Benefit_Grid!$C$5:$AU$5) -> 21639.863 | N10: 204697.4 | O10: =L10-N10 -> 1.5413389e-07
A11: E006 | B11: 32623 | C11: 42793 | D11: 51100 | E11: =(Assumptions!$B$6-B11)/365.25 -> 36.930869 | F11: =(Assumptions!$B$6-C11)/365.25 -> 9.0869268 | G11: =INT(E11) -> 36 | H11: =Assumptions!$B$7-G11 -> 24 | I11: =INT(F11)+IF(F11-INT(F11)>0.5,1,0) -> 9 | J11: =MIN(15/26*D11*I11,Assumptions!$B$10) -> 265326.92 | K11: =IF(F11>=Assumptions!$B$11,1,0) -> 1 | L11: =SUMPRODUCT(Benefit_Grid!$C11:$AU11*(F11/(F11+Benefit_Grid!$C$5:$AU$5))*(1/(1+Assumptions!$B$8))^Benefit_Grid!$C$5:$AU$5) -> 206758.63 | M11: =SUMPRODUCT(Benefit_Grid!$C11:$AU11/(F11+Benefit_Grid!$C$5:$AU$5)*(1/(1+Assumptions!$B$8))^Benefit_Grid!$C$5:$AU$5) -> 22753.417 | N11: 206758.63 | O11: =L11-N11 -> -4.0023588e-07
A12: E007 | B12: 33233 | C12: 42799 | D12: 49800 | E12: =(Assumptions!$B$6-B12)/365.25 -> 35.26078 | F12: =(Assumptions!$B$6-C12)/365.25 -> 9.0704997 | G12: =INT(E12) -> 35 | H12: =Assumptions!$B$7-G12 -> 25 | I12: =INT(F12)+IF(F12-INT(F12)>0.5,1,0) -> 9 | J12: =MIN(15/26*D12*I12,Assumptions!$B$10) -> 258576.92 | K12: =IF(F12>=Assumptions!$B$11,1,0) -> 1 | L12: =SUMPRODUCT(Benefit_Grid!$C12:$AU12*(F12/(F12+Benefit_Grid!$C$5:$AU$5))*(1/(1+Assumptions!$B$8))^Benefit_Grid!$C$5:$AU$5) -> 203499.05 | M12: =SUMPRODUCT(Benefit_Grid!$C12:$AU12/(F12+Benefit_Grid!$C$5:$AU$5)*(1/(1+Assumptions!$B$8))^Benefit_Grid!$C$5:$AU$5) -> 22435.263 | N12: 203499.05 | O12: =L12-N12 -> -5.387119e-08
A13: E008 | B13: 33325 | C13: 42524 | D13: 45700 | E13: =(Assumptions!$B$6-B13)/365.25 -> 35.008898 | F13: =(Assumptions!$B$6-C13)/365.25 -> 9.8234086 | G13: =INT(E13) -> 35 | H13: =Assumptions!$B$7-G13 -> 25 | I13: =INT(F13)+IF(F13-INT(F13)>0.5,1,0) -> 10 | J13: =MIN(15/26*D13*I13,Assumptions!$B$10) -> 263653.85 | K13: =IF(F13>=Assumptions!$B$11,1,0) -> 1 | L13: =SUMPRODUCT(Benefit_Grid!$C13:$AU13*(F13/(F13+Benefit_Grid!$C$5:$AU$5))*(1/(1+Assumptions!$B$8))^Benefit_Grid!$C$5:$AU$5) -> 208166.93 | M13: =SUMPRODUCT(Benefit_Grid!$C13:$AU13/(F13+Benefit_Grid!$C$5:$AU$5)*(1/(1+Assumptions!$B$8))^Benefit_Grid!$C$5:$AU$5) -> 21190.906 | N13: 208166.93 | O13: =L13-N13 -> 1.9473373e-07
A14: E009 | B14: 33971 | C14: 45857 | D14: 25500 | E14: =(Assumptions!$B$6-B14)/365.25 -> 33.240246 | F14: =(Assumptions!$B$6-C14)/365.25 -> 0.69815195 | G14: =INT(E14) -> 33 | H14: =Assumptions!$B$7-G14 -> 27 | I14: =INT(F14)+IF(F14-INT(F14)>0.5,1,0) -> 1 | J14: =MIN(15/26*D14*I14,Assumptions!$B$10) -> 14711.538 | K14: =IF(F14>=Assumptions!$B$11,1,0) -> 0 | L14: =SUMPRODUCT(Benefit_Grid!$C14:$AU14*(F14/(F14+Benefit_Grid!$C$5:$AU$5))*(1/(1+Assumptions!$B$8))^Benefit_Grid!$C$5:$AU$5) -> 6804.4051 | M14: =SUMPRODUCT(Benefit_Grid!$C14:$AU14/(F14+Benefit_Grid!$C$5:$AU$5)*(1/(1+Assumptions!$B$8))^Benefit_Grid!$C$5:$AU$5) -> 9746.3097 | N14: 6804.4051 | O14: =L14-N14 -> 2.8066734e-07
A15: E010 | B15: 28454 | C15: 38107 | D15: 165000 | E15: =(Assumptions!$B$6-B15)/365.25 -> 48.344969 | F15: =(Assumptions!$B$6-C15)/365.25 -> 21.916496 | G15: =INT(E15) -> 48 | H15: =Assumptions!$B$7-G15 -> 12 | I15: =INT(F15)+IF(F15-INT(F15)>0.5,1,0) -> 22 | J15: =MIN(15/26*D15*I15,Assumptions!$B$10) -> 2000000 | K15: =IF(F15>=Assumptions!$B$11,1,0) -> 1 | L15: =SUMPRODUCT(Benefit_Grid!$C15:$AU15*(F15/(F15+Benefit_Grid!$C$5:$AU$5))*(1/(1+Assumptions!$B$8))^Benefit_Grid!$C$5:$AU$5) -> 716430.24 | M15: =SUMPRODUCT(Benefit_Grid!$C15:$AU15/(F15+Benefit_Grid!$C$5:$AU$5)*(1/(1+Assumptions!$B$8))^Benefit_Grid!$C$5:$AU$5) -> 32689.088 | N15: 716430.24 | O15: =L15-N15 -> -3.7171412e-07
A16: E011 | B16: 34533 | C16: 44930 | D16: 32700 | E16: =(Assumptions!$B$6-B16)/365.25 -> 31.701574 | F16: =(Assumptions!$B$6-C16)/365.25 -> 3.2361396 | G16: =INT(E16) -> 31 | H16: =Assumptions!$B$7-G16 -> 29 | I16: =INT(F16)+IF(F16-INT(F16)>0.5,1,0) -> 3 | J16: =MIN(15/26*D16*I16,Assumptions!$B$10) -> 56596.154 | K16: =IF(F16>=Assumptions!$B$11,1,0) -> 0 | L16: =SUMPRODUCT(Benefit_Grid!$C16:$AU16*(F16/(F16+Benefit_Grid!$C$5:$AU$5))*(1/(1+Assumptions!$B$8))^Benefit_Grid!$C$5:$AU$5) -> 47952.243 | M16: =SUMPRODUCT(Benefit_Grid!$C16:$AU16/(F16+Benefit_Grid!$C$5:$AU$5)*(1/(1+Assumptions!$B$8))^Benefit_Grid!$C$5:$AU$5) -> 14817.73 | N16: 47952.243 | O16: =L16-N16 -> -2.2353197e-07
A17: E012 | B17: 32170 | C17: 41013 | D17: 139100 | E17: =(Assumptions!$B$6-B17)/365.25 -> 38.171116 | F17: =(Assumptions!$B$6-C17)/365.25 -> 13.960301 | G17: =INT(E17) -> 38 | H17: =Assumptions!$B$7-G17 -> 22 | I17: =INT(F17)+IF(F17-INT(F17)>0.5,1,0) -> 14 | J17: =MIN(15/26*D17*I17,Assumptions!$B$10) -> 1123500 | K17: =IF(F17>=Assumptions!$B$11,1,0) -> 1 | L17: =SUMPRODUCT(Benefit_Grid!$C17:$AU17*(F17/(F17+Benefit_Grid!$C$5:$AU$5))*(1/(1+Assumptions!$B$8))^Benefit_Grid!$C$5:$AU$5) -> 548205.22 | M17: =SUMPRODUCT(Benefit_Grid!$C17:$AU17/(F17+Benefit_Grid!$C$5:$AU$5)*(1/(1+Assumptions!$B$8))^Benefit_Grid!$C$5:$AU$5) -> 39268.867 | N17: 548205.22 | O17: =L17-N17 -> 3.8207509e-07
... A155: E150 | B155: 29779 | C155: 40610 | D155: 67300 | E155: =(Assumptions!$B$6-B155)/365.25 -> 44.717317 | F155: =(Assumptions!$B$6-C155)/365.25 -> 15.063655 | G155: =INT(E155) -> 44 | H155: =Assumptions!$B$7-G155 -> 16 | I155: =INT(F155)+IF(F155-INT(F155)>0.5,1,0) -> 15 | J155: =MIN(15/26*D155*I155,Assumptions!$B$10) -> 582403.85 | K155: =IF(F155>=Assumptions!$B$11,1,0) -> 1 | L155: =SUMPRODUCT(Benefit_Grid!$C155:$AU155*(F155/(F155+Benefit_Grid!$C$5:$AU$5))*(1/(1+Assumptions!$B$8))^Benefit_Grid!$C$5:$AU$5) -> 410715.84 | M155: =SUMPRODUCT(Benefit_Grid!$C155:$AU155/(F155+Benefit_Grid!$C$5:$AU$5)*(1/(1+Assumptions!$B$8))^Benefit_Grid!$C$5:$AU$5) -> 27265.351 | N155: 410715.84 | O155: =L155-N155 -> 2.7823262e-08

Sheet Decrements
A1: Decrement table by age
A2: q = death probability, w = withdrawal probability. Combined so the two do not double count: death = q(1 - w/2), withdrawal = w(1 - q/2). L = probability of still being in service at the start of that age, starting from 1 at age 18.
A5: Age | B5: q (death) | C5: w (withdrawal) | D5: Death decrement | E5: Withdrawal decrement | F5: Stay in service | G5: In service at start of age (L)
A6: 18 | B6: =1-EXP(-(Assumptions!$B$12+Assumptions!$B$13*Assumptions!$B$14^A6*(Assumptions!$B$14-1)/LN(Assumptions!$B$14))) -> 0.00051653651 | C6: =VLOOKUP(A6,Assumptions!$A$19:$C$27,3,TRUE()) -> 0.2 | D6: =B6*(1-C6/2) -> 0.00046488286 | E6: =C6*(1-B6/2) -> 0.19994835 | F6: =1-D6-E6 -> 0.79958677 | G6: 1
A7: =A6+1 -> 19 | B7: =1-EXP(-(Assumptions!$B$12+Assumptions!$B$13*Assumptions!$B$14^A7*(Assumptions!$B$14-1)/LN(Assumptions!$B$14))) -> 0.00052819741 | C7: =VLOOKUP(A7,Assumptions!$A$19:$C$27,3,TRUE()) -> 0.2 | D7: =B7*(1-C7/2) -> 0.00047537767 | E7: =C7*(1-B7/2) -> 0.19994718 | F7: =1-D7-E7 -> 0.79957744 | G7: =G6*F6 -> 0.79958677
A8: =A7+1 -> 20 | B8: =1-EXP(-(Assumptions!$B$12+Assumptions!$B$13*Assumptions!$B$14^A8*(Assumptions!$B$14-1)/LN(Assumptions!$B$14))) -> 0.00054102424 | C8: =VLOOKUP(A8,Assumptions!$A$19:$C$27,3,TRUE()) -> 0.2 | D8: =B8*(1-C8/2) -> 0.00048692182 | E8: =C8*(1-B8/2) -> 0.1999459 | F8: =1-D8-E8 -> 0.79956718 | G8: =G7*F7 -> 0.63933154
A9: =A8+1 -> 21 | B9: =1-EXP(-(Assumptions!$B$12+Assumptions!$B$13*Assumptions!$B$14^A9*(Assumptions!$B$14-1)/LN(Assumptions!$B$14))) -> 0.00055513357 | C9: =VLOOKUP(A9,Assumptions!$A$19:$C$27,3,TRUE()) -> 0.2 | D9: =B9*(1-C9/2) -> 0.00049962021 | E9: =C9*(1-B9/2) -> 0.19994449 | F9: =1-D9-E9 -> 0.79955589 | G9: =G8*F8 -> 0.51118852
A10: =A9+1 -> 22 | B10: =1-EXP(-(Assumptions!$B$12+Assumptions!$B$13*Assumptions!$B$14^A10*(Assumptions!$B$14-1)/LN(Assumptions!$B$14))) -> 0.0005706536 | C10: =VLOOKUP(A10,Assumptions!$A$19:$C$27,3,TRUE()) -> 0.2 | D10: =B10*(1-C10/2) -> 0.00051358824 | E10: =C10*(1-B10/2) -> 0.19994293 | F10: =1-D10-E10 -> 0.79954348 | G10: =G9*F9 -> 0.40872379
A11: =A10+1 -> 23 | B11: =1-EXP(-(Assumptions!$B$12+Assumptions!$B$13*Assumptions!$B$14^A11*(Assumptions!$B$14-1)/LN(Assumptions!$B$14))) -> 0.00058772536 | C11: =VLOOKUP(A11,Assumptions!$A$19:$C$27,3,TRUE()) -> 0.2 | D11: =B11*(1-C11/2) -> 0.00052895282 | E11: =C11*(1-B11/2) -> 0.19994123 | F11: =1-D11-E11 -> 0.79952982 | G11: =G10*F10 -> 0.32679244
A12: =A11+1 -> 24 | B12: =1-EXP(-(Assumptions!$B$12+Assumptions!$B$13*Assumptions!$B$14^A12*(Assumptions!$B$14-1)/LN(Assumptions!$B$14))) -> 0.00060650395 | C12: =VLOOKUP(A12,Assumptions!$A$19:$C$27,3,TRUE()) -> 0.2 | D12: =B12*(1-C12/2) -> 0.00054585355 | E12: =C12*(1-B12/2) -> 0.19993935 | F12: =1-D12-E12 -> 0.7995148 | G12: =G11*F11 -> 0.2612803
A13: =A12+1 -> 25 | B13: =1-EXP(-(Assumptions!$B$12+Assumptions!$B$13*Assumptions!$B$14^A13*(Assumptions!$B$14-1)/LN(Assumptions!$B$14))) -> 0.00062715999 | C13: =VLOOKUP(A13,Assumptions!$A$19:$C$27,3,TRUE()) -> 0.15 | D13: =B13*(1-C13/2) -> 0.00058012299 | E13: =C13*(1-B13/2) -> 0.14995296 | F13: =1-D13-E13 -> 0.84946691 | G13: =G12*F12 -> 0.20889747
A14: =A13+1 -> 26 | B14: =1-EXP(-(Assumptions!$B$12+Assumptions!$B$13*Assumptions!$B$14^A14*(Assumptions!$B$14-1)/LN(Assumptions!$B$14))) -> 0.00064988115 | C14: =VLOOKUP(A14,Assumptions!$A$19:$C$27,3,TRUE()) -> 0.15 | D14: =B14*(1-C14/2) -> 0.00060114006 | E14: =C14*(1-B14/2) -> 0.14995126 | F14: =1-D14-E14 -> 0.8494476 | G14: =G13*F13 -> 0.17745149
A15: =A14+1 -> 27 | B15: =1-EXP(-(Assumptions!$B$12+Assumptions!$B$13*Assumptions!$B$14^A15*(Assumptions!$B$14-1)/LN(Assumptions!$B$14))) -> 0.00067487383 | C15: =VLOOKUP(A15,Assumptions!$A$19:$C$27,3,TRUE()) -> 0.15 | D15: =B15*(1-C15/2) -> 0.00062425829 | E15: =C15*(1-B15/2) -> 0.14994938 | F15: =1-D15-E15 -> 0.84942636 | G15: =G14*F14 -> 0.15073574
A16: =A15+1 -> 28 | B16: =1-EXP(-(Assumptions!$B$12+Assumptions!$B$13*Assumptions!$B$14^A16*(Assumptions!$B$14-1)/LN(Assumptions!$B$14))) -> 0.00070236505 | C16: =VLOOKUP(A16,Assumptions!$A$19:$C$27,3,TRUE()) -> 0.15 | D16: =B16*(1-C16/2) -> 0.00064968767 | E16: =C16*(1-B16/2) -> 0.14994732 | F16: =1-D16-E16 -> 0.84940299 | G16: =G15*F15 -> 0.12803891
A17: =A16+1 -> 29 | B17: =1-EXP(-(Assumptions!$B$12+Assumptions!$B$13*Assumptions!$B$14^A17*(Assumptions!$B$14-1)/LN(Assumptions!$B$14))) -> 0.00073260452 | C17: =VLOOKUP(A17,Assumptions!$A$19:$C$27,3,TRUE()) -> 0.15 | D17: =B17*(1-C17/2) -> 0.00067765918 | E17: =C17*(1-B17/2) -> 0.14994505 | F17: =1-D17-E17 -> 0.84937729 | G17: =G16*F16 -> 0.10875663
A18: =A17+1 -> 30 | B18: =1-EXP(-(Assumptions!$B$12+Assumptions!$B$13*Assumptions!$B$14^A18*(Assumptions!$B$14-1)/LN(Assumptions!$B$14))) -> 0.00076586688 | C18: =VLOOKUP(A18,Assumptions!$A$19:$C$27,3,TRUE()) -> 0.11 | D18: =B18*(1-C18/2) -> 0.0007237442 | E18: =C18*(1-B18/2) -> 0.10995788 | F18: =1-D18-E18 -> 0.88931838 | G18: =G17*F17 -> 0.092375415
... A58: =A57+1 -> 70 | B58: =1-EXP(-(Assumptions!$B$12+Assumptions!$B$13*Assumptions!$B$14^A58*(Assumptions!$B$14-1)/LN(Assumptions!$B$14))) -> 0.016828927 | C58: =VLOOKUP(A58,Assumptions!$A$19:$C$27,3,TRUE()) -> 0 | D58: =B58*(1-C58/2) -> 0.016828927 | E58: =C58*(1-B58/2) -> 0 | F58: =1-D58-E58 -> 0.98317107 | G58: =G57*F57 -> 0.016251678

Sheet Benefit_Grid
A1: Expected benefit payable at the end of each future year (Rs), before attribution and discounting
A2: Each cell = P(paid in year t) x benefit at exit, with the part-year rule, wage growth, ceiling, and the five-year rule for withdrawals. Death and retirement are paid regardless of service length.
A3: Row numbers match the Census sheet. Columns are years from the valuation date (t).
A5: Emp ID | B5: Years to retirement | C5: 1 | D5: =C5+1 -> 2 | E5: =D5+1 -> 3 | F5: =E5+1 -> 4 | G5: =F5+1 -> 5 | H5: =G5+1 -> 6 | I5: =H5+1 -> 7 | J5: =I5+1 -> 8 | K5: =J5+1 -> 9 | ... AU5: =AT5+1 -> 45
A6: =Census!A6 -> E001 | B6: =Census!H6 -> 30 | C6: =IF(C$5>$B6,0,INDEX(Decrements!$G$6:$G$58,Census!$G6+C$5-18)/INDEX(Decrements!$G$6:$G$58,Census!$G6-17)*(INDEX(Decrements!$D$6:$D$58,Census!$G6+C$5-18)+IF(C$5=$B6,INDEX(Decrements!$F$6:$F$58,Census!$G6+C$5-18),0)+INDEX(Decrements!$E$6:$E$58,Census!$G6+C$5-18)*IF((Census!$F6+C$5)>=Assumptions!$B$11,1,0))*MIN(15/26*Census!$D6*(1+Assumptions!$B$9)^C$5*(INT((Census!$F6+C$5))+IF((Census!$F6+C$5)-INT((Census!$F6+C$5))>0.5,1,0)),Assumptions!$B$10)) -> 42.7499 | D6: =IF(D$5>$B6,0,INDEX(Decrements!$G$6:$G$58,Census!$G6+D$5-18)/INDEX(Decrements!$G$6:$G$58,Census!$G6-17)*(INDEX(Decrements!$D$6:$D$58,Census!$G6+D$5-18)+IF(D$5=$B6,INDEX(Decrements!$F$6:$F$58,Census!$G6+D$5-18),0)+INDEX(Decrements!$E$6:$E$58,Census!$G6+D$5-18)*IF((Census!$F6+D$5)>=Assumptions!$B$11,1,0))*MIN(15/26*Census!$D6*(1+Assumptions!$B$9)^D$5*(INT((Census!$F6+D$5))+IF((Census!$F6+D$5)-INT((Census!$F6+D$5))>0.5,1,0)),Assumptions!$B$10)) -> 7851.3494 | E6: =IF(E$5>$B6,0,INDEX(Decrements!$G$6:$G$58,Census!$G6+E$5-18)/INDEX(Decrements!$G$6:$G$58,Census!$G6-17)*(INDEX(Decrements!$D$6:$D$58,Census!$G6+E$5-18)+IF(E$5=$B6,INDEX(Decrements!$F$6:$F$58,Census!$G6+E$5-18),0)+INDEX(Decrements!$E$6:$E$58,Census!$G6+E$5-18)*IF((Census!$F6+E$5)>=Assumptions!$B$11,1,0))*MIN(15/26*Census!$D6*(1+Assumptions!$B$9)^E$5*(INT((Census!$F6+E$5))+IF((Census!$F6+E$5)-INT((Census!$F6+E$5))>0.5,1,0)),Assumptions!$B$10)) -> 9051.7208 | F6: =IF(F$5>$B6,0,INDEX(Decrements!$G$6:$G$58,Census!$G6+F$5-18)/INDEX(Decrements!$G$6:$G$58,Census!$G6-17)*(INDEX(Decrements!$D$6:$D$58,Census!$G6+F$5-18)+IF(F$5=$B6,INDEX(Decrements!$F$6:$F$58,Census!$G6+F$5-18),0)+INDEX(Decrements!$E$6:$E$58,Census!$G6+F$5-18)*IF((Census!$F6+F$5)>=Assumptions!$B$11,1,0))*MIN(15/26*Census!$D6*(1+Assumptions!$B$9)^F$5*(INT((Census!$F6+F$5))+IF((Census!$F6+F$5)-INT((Census!$F6+F$5))>0.5,1,0)),Assumptions!$B$10)) -> 10145.654 | G6: =IF(G$5>$B6,0,INDEX(Decrements!$G$6:$G$58,Census!$G6+G$5-18)/INDEX(Decrements!$G$6:$G$58,Census!$G6-17)*(INDEX(Decrements!$D$6:$D$58,Census!$G6+G$5-18)+IF(G$5=$B6,INDEX(Decrements!$F$6:$F$58,Census!$G6+G$5-18),0)+INDEX(Decrements!$E$6:$E$58,Census!$G6+G$5-18)*IF((Census!$F6+G$5)>=Assumptions!$B$11,1,0))*MIN(15/26*Census!$D6*(1+Assumptions!$B$9)^G$5*(INT((Census!$F6+G$5))+IF((Census!$F6+G$5)-INT((Census!$F6+G$5))>0.5,1,0)),Assumptions!$B$10)) -> 11139.616 | H6: =IF(H$5>$B6,0,INDEX(Decrements!$G$6:$G$58,Census!$G6+H$5-18)/INDEX(Decrements!$G$6:$G$58,Census!$G6-17)*(INDEX(Decrements!$D$6:$D$58,Census!$G6+H$5-18)+IF(H$5=$B6,INDEX(Decrements!$F$6:$F$58,Census!$G6+H$5-18),0)+INDEX(Decrements!$E$6:$E$58,Census!$G6+H$5-18)*IF((Census!$F6+H$5)>=Assumptions!$B$11,1,0))*MIN(15/26*Census!$D6*(1+Assumptions!$B$9)^H$5*(INT((Census!$F6+H$5))+IF((Census!$F6+H$5)-INT((Census!$F6+H$5))>0.5,1,0)),Assumptions!$B$10)) -> 8785.4603 | I6: =IF(I$5>$B6,0,INDEX(Decrements!$G$6:$G$58,Census!$G6+I$5-18)/INDEX(Decrements!$G$6:$G$58,Census!$G6-17)*(INDEX(Decrements!$D$6:$D$58,Census!$G6+I$5-18)+IF(I$5=$B6,INDEX(Decrements!$F$6:$F$58,Census!$G6+I$5-18),0)+INDEX(Decrements!$E$6:$E$58,Census!$G6+I$5-18)*IF((Census!$F6+I$5)>=Assumptions!$B$11,1,0))*MIN(15/26*Census!$D6*(1+Assumptions!$B$9)^I$5*(INT((Census!$F6+I$5))+IF((Census!$F6+I$5)-INT((Census!$F6+I$5))>0.5,1,0)),Assumptions!$B$10)) -> 9696.0442 | J6: =IF(J$5>$B6,0,INDEX(Decrements!$G$6:$G$58,Census!$G6+J$5-18)/INDEX(Decrements!$G$6:$G$58,Census!$G6-17)*(INDEX(Decrements!$D$6:$D$58,Census!$G6+J$5-18)+IF(J$5=$B6,INDEX(Decrements!$F$6:$F$58,Census!$G6+J$5-18),0)+INDEX(Decrements!$E$6:$E$58,Census!$G6+J$5-18)*IF((Census!$F6+J$5)>=Assumptions!$B$11,1,0))*MIN(15/26*Census!$D6*(1+Assumptions!$B$9)^J$5*(INT((Census!$F6+J$5))+IF((Census!$F6+J$5)-INT((Census!$F6+J$5))>0.5,1,0)),Assumptions!$B$10)) -> 10594.076 | ... AU6: =IF(AU$5>$B6,0,INDEX(Decrements!$G$6:$G$58,Census!$G6+AU$5-18)/INDEX(Decrements!$G$6:$G$58,Census!$G6-17)*(INDEX(Decrements!$D$6:$D$58,Census!$G6+AU$5-18)+IF(AU$5=$B6,INDEX(Decrements!$F$6:$F$58,Census!$G6+AU$5-18),0)+INDEX(Decrements!$E$6:$E$58,Census!$G6+AU$5-18)*IF((Census!$F6+AU$5)>=Assumptions!$B$11,1,0))*MIN(15/26*Census!$D6*(1+Assumptions!$B$9)^AU$5*(INT((Census!$F6+AU$5))+IF((Census!$F6+AU$5)-INT((Census!$F6+AU$5))>0.5,1,0)),Assumptions!$B$10)) -> 0
A7: =Census!A7 -> E002 | B7: =Census!H7 -> 27 | C7: =IF(C$5>$B7,0,INDEX(Decrements!$G$6:$G$58,Census!$G7+C$5-18)/INDEX(Decrements!$G$6:$G$58,Census!$G7-17)*(INDEX(Decrements!$D$6:$D$58,Census!$G7+C$5-18)+IF(C$5=$B7,INDEX(Decrements!$F$6:$F$58,Census!$G7+C$5-18),0)+INDEX(Decrements!$E$6:$E$58,Census!$G7+C$5-18)*IF((Census!$F7+C$5)>=Assumptions!$B$11,1,0))*MIN(15/26*Census!$D7*(1+Assumptions!$B$9)^C$5*(INT((Census!$F7+C$5))+IF((Census!$F7+C$5)-INT((Census!$F7+C$5))>0.5,1,0)),Assumptions!$B$10)) -> 69.981805 | D7: =IF(D$5>$B7,0,INDEX(Decrements!$G$6:$G$58,Census!$G7+D$5-18)/INDEX(Decrements!$G$6:$G$58,Census!$G7-17)*(INDEX(Decrements!$D$6:$D$58,Census!$G7+D$5-18)+IF(D$5=$B7,INDEX(Decrements!$F$6:$F$58,Census!$G7+D$5-18),0)+INDEX(Decrements!$E$6:$E$58,Census!$G7+D$5-18)*IF((Census!$F7+D$5)>=Assumptions!$B$11,1,0))*MIN(15/26*Census!$D7*(1+Assumptions!$B$9)^D$5*(INT((Census!$F7+D$5))+IF((Census!$F7+D$5)-INT((Census!$F7+D$5))>0.5,1,0)),Assumptions!$B$10)) -> 88.620355 | E7: =IF(E$5>$B7,0,INDEX(Decrements!$G$6:$G$58,Census!$G7+E$5-18)/INDEX(Decrements!$G$6:$G$58,Census!$G7-17)*(INDEX(Decrements!$D$6:$D$58,Census!$G7+E$5-18)+IF(E$5=$B7,INDEX(Decrements!$F$6:$F$58,Census!$G7+E$5-18),0)+INDEX(Decrements!$E$6:$E$58,Census!$G7+E$5-18)*IF((Census!$F7+E$5)>=Assumptions!$B$11,1,0))*MIN(15/26*Census!$D7*(1+Assumptions!$B$9)^E$5*(INT((Census!$F7+E$5))+IF((Census!$F7+E$5)-INT((Census!$F7+E$5))>0.5,1,0)),Assumptions!$B$10)) -> 9344.9278 | F7: =IF(F$5>$B7,0,INDEX(Decrements!$G$6:$G$58,Census!$G7+F$5-18)/INDEX(Decrements!$G$6:$G$58,Census!$G7-17)*(INDEX(Decrements!$D$6:$D$58,Census!$G7+F$5-18)+IF(F$5=$B7,INDEX(Decrements!$F$6:$F$58,Census!$G7+F$5-18),0)+INDEX(Decrements!$E$6:$E$58,Census!$G7+F$5-18)*IF((Census!$F7+F$5)>=Assumptions!$B$11,1,0))*MIN(15/26*Census!$D7*(1+Assumptions!$B$9)^F$5*(INT((Census!$F7+F$5))+IF((Census!$F7+F$5)-INT((Census!$F7+F$5))>0.5,1,0)),Assumptions!$B$10)) -> 10829.174 | G7: =IF(G$5>$B7,0,INDEX(Decrements!$G$6:$G$58,Census!$G7+G$5-18)/INDEX(Decrements!$G$6:$G$58,Census!$G7-17)*(INDEX(Decrements!$D$6:$D$58,Census!$G7+G$5-18)+IF(G$5=$B7,INDEX(Decrements!$F$6:$F$58,Census!$G7+G$5-18),0)+INDEX(Decrements!$E$6:$E$58,Census!$G7+G$5-18)*IF((Census!$F7+G$5)>=Assumptions!$B$11,1,0))*MIN(15/26*Census!$D7*(1+Assumptions!$B$9)^G$5*(INT((Census!$F7+G$5))+IF((Census!$F7+G$5)-INT((Census!$F7+G$5))>0.5,1,0)),Assumptions!$B$10)) -> 12293.147 | H7: =IF(H$5>$B7,0,INDEX(Decrements!$G$6:$G$58,Census!$G7+H$5-18)/INDEX(Decrements!$G$6:$G$58,Census!$G7-17)*(INDEX(Decrements!$D$6:$D$58,Census!$G7+H$5-18)+IF(H$5=$B7,INDEX(Decrements!$F$6:$F$58,Census!$G7+H$5-18),0)+INDEX(Decrements!$E$6:$E$58,Census!$G7+H$5-18)*IF((Census!$F7+H$5)>=Assumptions!$B$11,1,0))*MIN(15/26*Census!$D7*(1+Assumptions!$B$9)^H$5*(INT((Census!$F7+H$5))+IF((Census!$F7+H$5)-INT((Census!$F7+H$5))>0.5,1,0)),Assumptions!$B$10)) -> 13737.094 | I7: =IF(I$5>$B7,0,INDEX(Decrements!$G$6:$G$58,Census!$G7+I$5-18)/INDEX(Decrements!$G$6:$G$58,Census!$G7-17)*(INDEX(Decrements!$D$6:$D$58,Census!$G7+I$5-18)+IF(I$5=$B7,INDEX(Decrements!$F$6:$F$58,Census!$G7+I$5-18),0)+INDEX(Decrements!$E$6:$E$58,Census!$G7+I$5-18)*IF((Census!$F7+I$5)>=Assumptions!$B$11,1,0))*MIN(15/26*Census!$D7*(1+Assumptions!$B$9)^I$5*(INT((Census!$F7+I$5))+IF((Census!$F7+I$5)-INT((Census!$F7+I$5))>0.5,1,0)),Assumptions!$B$10)) -> 15161.266 | J7: =IF(J$5>$B7,0,INDEX(Decrements!$G$6:$G$58,Census!$G7+J$5-18)/INDEX(Decrements!$G$6:$G$58,Census!$G7-17)*(INDEX(Decrements!$D$6:$D$58,Census!$G7+J$5-18)+IF(J$5=$B7,INDEX(Decrements!$F$6:$F$58,Census!$G7+J$5-18),0)+INDEX(Decrements!$E$6:$E$58,Census!$G7+J$5-18)*IF((Census!$F7+J$5)>=Assumptions!$B$11,1,0))*MIN(15/26*Census!$D7*(1+Assumptions!$B$9)^J$5*(INT((Census!$F7+J$5))+IF((Census!$F7+J$5)-INT((Census!$F7+J$5))>0.5,1,0)),Assumptions!$B$10)) -> 10456.834 | ... AU7: =IF(AU$5>$B7,0,INDEX(Decrements!$G$6:$G$58,Census!$G7+AU$5-18)/INDEX(Decrements!$G$6:$G$58,Census!$G7-17)*(INDEX(Decrements!$D$6:$D$58,Census!$G7+AU$5-18)+IF(AU$5=$B7,INDEX(Decrements!$F$6:$F$58,Census!$G7+AU$5-18),0)+INDEX(Decrements!$E$6:$E$58,Census!$G7+AU$5-18)*IF((Census!$F7+AU$5)>=Assumptions!$B$11,1,0))*MIN(15/26*Census!$D7*(1+Assumptions!$B$9)^AU$5*(INT((Census!$F7+AU$5))+IF((Census!$F7+AU$5)-INT((Census!$F7+AU$5))>0.5,1,0)),Assumptions!$B$10)) -> 0
A8: =Census!A8 -> E003 | B8: =Census!H8 -> 21 | C8: =IF(C$5>$B8,0,INDEX(Decrements!$G$6:$G$58,Census!$G8+C$5-18)/INDEX(Decrements!$G$6:$G$58,Census!$G8-17)*(INDEX(Decrements!$D$6:$D$58,Census!$G8+C$5-18)+IF(C$5=$B8,INDEX(Decrements!$F$6:$F$58,Census!$G8+C$5-18),0)+INDEX(Decrements!$E$6:$E$58,Census!$G8+C$5-18)*IF((Census!$F8+C$5)>=Assumptions!$B$11,1,0))*MIN(15/26*Census!$D8*(1+Assumptions!$B$9)^C$5*(INT((Census!$F8+C$5))+IF((Census!$F8+C$5)-INT((Census!$F8+C$5))>0.5,1,0)),Assumptions!$B$10)) -> 75399.734 | D8: =IF(D$5>$B8,0,INDEX(Decrements!$G$6:$G$58,Census!$G8+D$5-18)/INDEX(Decrements!$G$6:$G$58,Census!$G8-17)*(INDEX(Decrements!$D$6:$D$58,Census!$G8+D$5-18)+IF(D$5=$B8,INDEX(Decrements!$F$6:$F$58,Census!$G8+D$5-18),0)+INDEX(Decrements!$E$6:$E$58,Census!$G8+D$5-18)*IF((Census!$F8+D$5)>=Assumptions!$B$11,1,0))*MIN(15/26*Census!$D8*(1+Assumptions!$B$9)^D$5*(INT((Census!$F8+D$5))+IF((Census!$F8+D$5)-INT((Census!$F8+D$5))>0.5,1,0)),Assumptions!$B$10)) -> 50427.866 | E8: =IF(E$5>$B8,0,INDEX(Decrements!$G$6:$G$58,Census!$G8+E$5-18)/INDEX(Decrements!$G$6:$G$58,Census!$G8-17)*(INDEX(Decrements!$D$6:$D$58,Census!$G8+E$5-18)+IF(E$5=$B8,INDEX(Decrements!$F$6:$F$58,Census!$G8+E$5-18),0)+INDEX(Decrements!$E$6:$E$58,Census!$G8+E$5-18)*IF((Census!$F8+E$5)>=Assumptions!$B$11,1,0))*MIN(15/26*Census!$D8*(1+Assumptions!$B$9)^E$5*(INT((Census!$F8+E$5))+IF((Census!$F8+E$5)-INT((Census!$F8+E$5))>0.5,1,0)),Assumptions!$B$10)) -> 54994.982 | F8: =IF(F$5>$B8,0,INDEX(Decrements!$G$6:$G$58,Census!$G8+F$5-18)/INDEX(Decrements!$G$6:$G$58,Census!$G8-17)*(INDEX(Decrements!$D$6:$D$58,Census!$G8+F$5-18)+IF(F$5=$B8,INDEX(Decrements!$F$6:$F$58,Census!$G8+F$5-18),0)+INDEX(Decrements!$E$6:$E$58,Census!$G8+F$5-18)*IF((Census!$F8+F$5)>=Assumptions!$B$11,1,0))*MIN(15/26*Census!$D8*(1+Assumptions!$B$9)^F$5*(INT((Census!$F8+F$5))+IF((Census!$F8+F$5)-INT((Census!$F8+F$5))>0.5,1,0)),Assumptions!$B$10)) -> 59772.794 | G8: =IF(G$5>$B8,0,INDEX(Decrements!$G$6:$G$58,Census!$G8+G$5-18)/INDEX(Decrements!$G$6:$G$58,Census!$G8-17)*(INDEX(Decrements!$D$6:$D$58,Census!$G8+G$5-18)+IF(G$5=$B8,INDEX(Decrements!$F$6:$F$58,Census!$G8+G$5-18),0)+INDEX(Decrements!$E$6:$E$58,Census!$G8+G$5-18)*IF((Census!$F8+G$5)>=Assumptions!$B$11,1,0))*MIN(15/26*Census!$D8*(1+Assumptions!$B$9)^G$5*(INT((Census!$F8+G$5))+IF((Census!$F8+G$5)-INT((Census!$F8+G$5))>0.5,1,0)),Assumptions!$B$10)) -> 64770.6 | H8: =IF(H$5>$B8,0,INDEX(Decrements!$G$6:$G$58,Census!$G8+H$5-18)/INDEX(Decrements!$G$6:$G$58,Census!$G8-17)*(INDEX(Decrements!$D$6:$D$58,Census!$G8+H$5-18)+IF(H$5=$B8,INDEX(Decrements!$F$6:$F$58,Census!$G8+H$5-18),0)+INDEX(Decrements!$E$6:$E$58,Census!$G8+H$5-18)*IF((Census!$F8+H$5)>=Assumptions!$B$11,1,0))*MIN(15/26*Census!$D8*(1+Assumptions!$B$9)^H$5*(INT((Census!$F8+H$5))+IF((Census!$F8+H$5)-INT((Census!$F8+H$5))>0.5,1,0)),Assumptions!$B$10)) -> 69998.25 | I8: =IF(I$5>$B8,0,INDEX(Decrements!$G$6:$G$58,Census!$G8+I$5-18)/INDEX(Decrements!$G$6:$G$58,Census!$G8-17)*(INDEX(Decrements!$D$6:$D$58,Census!$G8+I$5-18)+IF(I$5=$B8,INDEX(Decrements!$F$6:$F$58,Census!$G8+I$5-18),0)+INDEX(Decrements!$E$6:$E$58,Census!$G8+I$5-18)*IF((Census!$F8+I$5)>=Assumptions!$B$11,1,0))*MIN(15/26*Census!$D8*(1+Assumptions!$B$9)^I$5*(INT((Census!$F8+I$5))+IF((Census!$F8+I$5)-INT((Census!$F8+I$5))>0.5,1,0)),Assumptions!$B$10)) -> 44965.612 | J8: =IF(J$5>$B8,0,INDEX(Decrements!$G$6:$G$58,Census!$G8+J$5-18)/INDEX(Decrements!$G$6:$G$58,Census!$G8-17)*(INDEX(Decrements!$D$6:$D$58,Census!$G8+J$5-18)+IF(J$5=$B8,INDEX(Decrements!$F$6:$F$58,Census!$G8+J$5-18),0)+INDEX(Decrements!$E$6:$E$58,Census!$G8+J$5-18)*IF((Census!$F8+J$5)>=Assumptions!$B$11,1,0))*MIN(15/26*Census!$D8*(1+Assumptions!$B$9)^J$5*(INT((Census!$F8+J$5))+IF((Census!$F8+J$5)-INT((Census!$F8+J$5))>0.5,1,0)),Assumptions!$B$10)) -> 43734.818 | ... AU8: =IF(AU$5>$B8,0,INDEX(Decrements!$G$6:$G$58,Census!$G8+AU$5-18)/INDEX(Decrements!$G$6:$G$58,Census!$G8-17)*(INDEX(Decrements!$D$6:$D$58,Census!$G8+AU$5-18)+IF(AU$5=$B8,INDEX(Decrements!$F$6:$F$58,Census!$G8+AU$5-18),0)+INDEX(Decrements!$E$6:$E$58,Census!$G8+AU$5-18)*IF((Census!$F8+AU$5)>=Assumptions!$B$11,1,0))*MIN(15/26*Census!$D8*(1+Assumptions!$B$9)^AU$5*(INT((Census!$F8+AU$5))+IF((Census!$F8+AU$5)-INT((Census!$F8+AU$5))>0.5,1,0)),Assumptions!$B$10)) -> 0
A9: =Census!A9 -> E004 | B9: =Census!H9 -> 21 | C9: =IF(C$5>$B9,0,INDEX(Decrements!$G$6:$G$58,Census!$G9+C$5-18)/INDEX(Decrements!$G$6:$G$58,Census!$G9-17)*(INDEX(Decrements!$D$6:$D$58,Census!$G9+C$5-18)+IF(C$5=$B9,INDEX(Decrements!$F$6:$F$58,Census!$G9+C$5-18),0)+INDEX(Decrements!$E$6:$E$58,Census!$G9+C$5-18)*IF((Census!$F9+C$5)>=Assumptions!$B$11,1,0))*MIN(15/26*Census!$D9*(1+Assumptions!$B$9)^C$5*(INT((Census!$F9+C$5))+IF((Census!$F9+C$5)-INT((Census!$F9+C$5))>0.5,1,0)),Assumptions!$B$10)) -> 15646.33 | D9: =IF(D$5>$B9,0,INDEX(Decrements!$G$6:$G$58,Census!$G9+D$5-18)/INDEX(Decrements!$G$6:$G$58,Census!$G9-17)*(INDEX(Decrements!$D$6:$D$58,Census!$G9+D$5-18)+IF(D$5=$B9,INDEX(Decrements!$F$6:$F$58,Census!$G9+D$5-18),0)+INDEX(Decrements!$E$6:$E$58,Census!$G9+D$5-18)*IF((Census!$F9+D$5)>=Assumptions!$B$11,1,0))*MIN(15/26*Census!$D9*(1+Assumptions!$B$9)^D$5*(INT((Census!$F9+D$5))+IF((Census!$F9+D$5)-INT((Census!$F9+D$5))>0.5,1,0)),Assumptions!$B$10)) -> 11211.829 | E9: =IF(E$5>$B9,0,INDEX(Decrements!$G$6:$G$58,Census!$G9+E$5-18)/INDEX(Decrements!$G$6:$G$58,Census!$G9-17)*(INDEX(Decrements!$D$6:$D$58,Census!$G9+E$5-18)+IF(E$5=$B9,INDEX(Decrements!$F$6:$F$58,Census!$G9+E$5-18),0)+INDEX(Decrements!$E$6:$E$58,Census!$G9+E$5-18)*IF((Census!$F9+E$5)>=Assumptions!$B$11,1,0))*MIN(15/26*Census!$D9*(1+Assumptions!$B$9)^E$5*(INT((Census!$F9+E$5))+IF((Census!$F9+E$5)-INT((Census!$F9+E$5))>0.5,1,0)),Assumptions!$B$10)) -> 12946.505 | F9: =IF(F$5>$B9,0,INDEX(Decrements!$G$6:$G$58,Census!$G9+F$5-18)/INDEX(Decrements!$G$6:$G$58,Census!$G9-17)*(INDEX(Decrements!$D$6:$D$58,Census!$G9+F$5-18)+IF(F$5=$B9,INDEX(Decrements!$F$6:$F$58,Census!$G9+F$5-18),0)+INDEX(Decrements!$E$6:$E$58,Census!$G9+F$5-18)*IF((Census!$F9+F$5)>=Assumptions!$B$11,1,0))*MIN(15/26*Census!$D9*(1+Assumptions!$B$9)^F$5*(INT((Census!$F9+F$5))+IF((Census!$F9+F$5)-INT((Census!$F9+F$5))>0.5,1,0)),Assumptions!$B$10)) -> 14766.138 | G9: =IF(G$5>$B9,0,INDEX(Decrements!$G$6:$G$58,Census!$G9+G$5-18)/INDEX(Decrements!$G$6:$G$58,Census!$G9-17)*(INDEX(Decrements!$D$6:$D$58,Census!$G9+G$5-18)+IF(G$5=$B9,INDEX(Decrements!$F$6:$F$58,Census!$G9+G$5-18),0)+INDEX(Decrements!$E$6:$E$58,Census!$G9+G$5-18)*IF((Census!$F9+G$5)>=Assumptions!$B$11,1,0))*MIN(15/26*Census!$D9*(1+Assumptions!$B$9)^G$5*(INT((Census!$F9+G$5))+IF((Census!$F9+G$5)-INT((Census!$F9+G$5))>0.5,1,0)),Assumptions!$B$10)) -> 16674.503 | H9: =IF(H$5>$B9,0,INDEX(Decrements!$G$6:$G$58,Census!$G9+H$5-18)/INDEX(Decrements!$G$6:$G$58,Census!$G9-17)*(INDEX(Decrements!$D$6:$D$58,Census!$G9+H$5-18)+IF(H$5=$B9,INDEX(Decrements!$F$6:$F$58,Census!$G9+H$5-18),0)+INDEX(Decrements!$E$6:$E$58,Census!$G9+H$5-18)*IF((Census!$F9+H$5)>=Assumptions!$B$11,1,0))*MIN(15/26*Census!$D9*(1+Assumptions!$B$9)^H$5*(INT((Census!$F9+H$5))+IF((Census!$F9+H$5)-INT((Census!$F9+H$5))>0.5,1,0)),Assumptions!$B$10)) -> 18675.59 | I9: =IF(I$5>$B9,0,INDEX(Decrements!$G$6:$G$58,Census!$G9+I$5-18)/INDEX(Decrements!$G$6:$G$58,Census!$G9-17)*(INDEX(Decrements!$D$6:$D$58,Census!$G9+I$5-18)+IF(I$5=$B9,INDEX(Decrements!$F$6:$F$58,Census!$G9+I$5-18),0)+INDEX(Decrements!$E$6:$E$58,Census!$G9+I$5-18)*IF((Census!$F9+I$5)>=Assumptions!$B$11,1,0))*MIN(15/26*Census!$D9*(1+Assumptions!$B$9)^I$5*(INT((Census!$F9+I$5))+IF((Census!$F9+I$5)-INT((Census!$F9+I$5))>0.5,1,0)),Assumptions!$B$10)) -> 12773.218 | J9: =IF(J$5>$B9,0,INDEX(Decrements!$G$6:$G$58,Census!$G9+J$5-18)/INDEX(Decrements!$G$6:$G$58,Census!$G9-17)*(INDEX(Decrements!$D$6:$D$58,Census!$G9+J$5-18)+IF(J$5=$B9,INDEX(Decrements!$F$6:$F$58,Census!$G9+J$5-18),0)+INDEX(Decrements!$E$6:$E$58,Census!$G9+J$5-18)*IF((Census!$F9+J$5)>=Assumptions!$B$11,1,0))*MIN(15/26*Census!$D9*(1+Assumptions!$B$9)^J$5*(INT((Census!$F9+J$5))+IF((Census!$F9+J$5)-INT((Census!$F9+J$5))>0.5,1,0)),Assumptions!$B$10)) -> 14449.592 | ... AU9: =IF(AU$5>$B9,0,INDEX(Decrements!$G$6:$G$58,Census!$G9+AU$5-18)/INDEX(Decrements!$G$6:$G$58,Census!$G9-17)*(INDEX(Decrements!$D$6:$D$58,Census!$G9+AU$5-18)+IF(AU$5=$B9,INDEX(Decrements!$F$6:$F$58,Census!$G9+AU$5-18),0)+INDEX(Decrements!$E$6:$E$58,Census!$G9+AU$5-18)*IF((Census!$F9+AU$5)>=Assumptions!$B$11,1,0))*MIN(15/26*Census!$D9*(1+Assumptions!$B$9)^AU$5*(INT((Census!$F9+AU$5))+IF((Census!$F9+AU$5)-INT((Census!$F9+AU$5))>0.5,1,0)),Assumptions!$B$10)) -> 0
A10: =Census!A10 -> E005 | B10: =Census!H10 -> 25 | C10: =IF(C$5>$B10,0,INDEX(Decrements!$G$6:$G$58,Census!$G10+C$5-18)/INDEX(Decrements!$G$6:$G$58,Census!$G10-17)*(INDEX(Decrements!$D$6:$D$58,Census!$G10+C$5-18)+IF(C$5=$B10,INDEX(Decrements!$F$6:$F$58,Census!$G10+C$5-18),0)+INDEX(Decrements!$E$6:$E$58,Census!$G10+C$5-18)*IF((Census!$F10+C$5)>=Assumptions!$B$11,1,0))*MIN(15/26*Census!$D10*(1+Assumptions!$B$9)^C$5*(INT((Census!$F10+C$5))+IF((Census!$F10+C$5)-INT((Census!$F10+C$5))>0.5,1,0)),Assumptions!$B$10)) -> 24702.469 | D10: =IF(D$5>$B10,0,INDEX(Decrements!$G$6:$G$58,Census!$G10+D$5-18)/INDEX(Decrements!$G$6:$G$58,Census!$G10-17)*(INDEX(Decrements!$D$6:$D$58,Census!$G10+D$5-18)+IF(D$5=$B10,INDEX(Decrements!$F$6:$F$58,Census!$G10+D$5-18),0)+INDEX(Decrements!$E$6:$E$58,Census!$G10+D$5-18)*IF((Census!$F10+D$5)>=Assumptions!$B$11,1,0))*MIN(15/26*Census!$D10*(1+Assumptions!$B$9)^D$5*(INT((Census!$F10+D$5))+IF((Census!$F10+D$5)-INT((Census!$F10+D$5))>0.5,1,0)),Assumptions!$B$10)) -> 26990.17 | E10: =IF(E$5>$B10,0,INDEX(Decrements!$G$6:$G$58,Census!$G10+E$5-18)/INDEX(Decrements!$G$6:$G$58,Census!$G10-17)*(INDEX(Decrements!$D$6:$D$58,Census!$G10+E$5-18)+IF(E$5=$B10,INDEX(Decrements!$F$6:$F$58,Census!$G10+E$5-18),0)+INDEX(Decrements!$E$6:$E$58,Census!$G10+E$5-18)*IF((Census!$F10+E$5)>=Assumptions!$B$11,1,0))*MIN(15/26*Census!$D10*(1+Assumptions!$B$9)^E$5*(INT((Census!$F10+E$5))+IF((Census!$F10+E$5)-INT((Census!$F10+E$5))>0.5,1,0)),Assumptions!$B$10)) -> 29246.236 | F10: =IF(F$5>$B10,0,INDEX(Decrements!$G$6:$G$58,Census!$G10+F$5-18)/INDEX(Decrements!$G$6:$G$58,Census!$G10-17)*(INDEX(Decrements!$D$6:$D$58,Census!$G10+F$5-18)+IF(F$5=$B10,INDEX(Decrements!$F$6:$F$58,Census!$G10+F$5-18),0)+INDEX(Decrements!$E$6:$E$58,Census!$G10+F$5-18)*IF((Census!$F10+F$5)>=Assumptions!$B$11,1,0))*MIN(15/26*Census!$D10*(1+Assumptions!$B$9)^F$5*(INT((Census!$F10+F$5))+IF((Census!$F10+F$5)-INT((Census!$F10+F$5))>0.5,1,0)),Assumptions!$B$10)) -> 31471.062 | G10: =IF(G$5>$B10,0,INDEX(Decrements!$G$6:$G$58,Census!$G10+G$5-18)/INDEX(Decrements!$G$6:$G$58,Census!$G10-17)*(INDEX(Decrements!$D$6:$D$58,Census!$G10+G$5-18)+IF(G$5=$B10,INDEX(Decrements!$F$6:$F$58,Census!$G10+G$5-18),0)+INDEX(Decrements!$E$6:$E$58,Census!$G10+G$5-18)*IF((Census!$F10+G$5)>=Assumptions!$B$11,1,0))*MIN(15/26*Census!$D10*(1+Assumptions!$B$9)^G$5*(INT((Census!$F10+G$5))+IF((Census!$F10+G$5)-INT((Census!$F10+G$5))>0.5,1,0)),Assumptions!$B$10)) -> 33665.042 | H10: =IF(H$5>$B10,0,INDEX(Decrements!$G$6:$G$58,Census!$G10+H$5-18)/INDEX(Decrements!$G$6:$G$58,Census!$G10-17)*(INDEX(Decrements!$D$6:$D$58,Census!$G10+H$5-18)+IF(H$5=$B10,INDEX(Decrements!$F$6:$F$58,Census!$G10+H$5-18),0)+INDEX(Decrements!$E$6:$E$58,Census!$G10+H$5-18)*IF((Census!$F10+H$5)>=Assumptions!$B$11,1,0))*MIN(15/26*Census!$D10*(1+Assumptions!$B$9)^H$5*(INT((Census!$F10+H$5))+IF((Census!$F10+H$5)-INT((Census!$F10+H$5))>0.5,1,0)),Assumptions!$B$10)) -> 22615.929 | I10: =IF(I$5>$B10,0,INDEX(Decrements!$G$6:$G$58,Census!$G10+I$5-18)/INDEX(Decrements!$G$6:$G$58,Census!$G10-17)*(INDEX(Decrements!$D$6:$D$58,Census!$G10+I$5-18)+IF(I$5=$B10,INDEX(Decrements!$F$6:$F$58,Census!$G10+I$5-18),0)+INDEX(Decrements!$E$6:$E$58,Census!$G10+I$5-18)*IF((Census!$F10+I$5)>=Assumptions!$B$11,1,0))*MIN(15/26*Census!$D10*(1+Assumptions!$B$9)^I$5*(INT((Census!$F10+I$5))+IF((Census!$F10+I$5)-INT((Census!$F10+I$5))>0.5,1,0)),Assumptions!$B$10)) -> 24760.916 | J10: =IF(J$5>$B10,0,INDEX(Decrements!$G$6:$G$58,Census!$G10+J$5-18)/INDEX(Decrements!$G$6:$G$58,Census!$G10-17)*(INDEX(Decrements!$D$6:$D$58,Census!$G10+J$5-18)+IF(J$5=$B10,INDEX(Decrements!$F$6:$F$58,Census!$G10+J$5-18),0)+INDEX(Decrements!$E$6:$E$58,Census!$G10+J$5-18)*IF((Census!$F10+J$5)>=Assumptions!$B$11,1,0))*MIN(15/26*Census!$D10*(1+Assumptions!$B$9)^J$5*(INT((Census!$F10+J$5))+IF((Census!$F10+J$5)-INT((Census!$F10+J$5))>0.5,1,0)),Assumptions!$B$10)) -> 27005.52 | ... AU10: =IF(AU$5>$B10,0,INDEX(Decrements!$G$6:$G$58,Census!$G10+AU$5-18)/INDEX(Decrements!$G$6:$G$58,Census!$G10-17)*(INDEX(Decrements!$D$6:$D$58,Census!$G10+AU$5-18)+IF(AU$5=$B10,INDEX(Decrements!$F$6:$F$58,Census!$G10+AU$5-18),0)+INDEX(Decrements!$E$6:$E$58,Census!$G10+AU$5-18)*IF((Census!$F10+AU$5)>=Assumptions!$B$11,1,0))*MIN(15/26*Census!$D10*(1+Assumptions!$B$9)^AU$5*(INT((Census!$F10+AU$5))+IF((Census!$F10+AU$5)-INT((Census!$F10+AU$5))>0.5,1,0)),Assumptions!$B$10)) -> 0
A11: =Census!A11 -> E006 | B11: =Census!H11 -> 24 | C11: =IF(C$5>$B11,0,INDEX(Decrements!$G$6:$G$58,Census!$G11+C$5-18)/INDEX(Decrements!$G$6:$G$58,Census!$G11-17)*(INDEX(Decrements!$D$6:$D$58,Census!$G11+C$5-18)+IF(C$5=$B11,INDEX(Decrements!$F$6:$F$58,Census!$G11+C$5-18),0)+INDEX(Decrements!$E$6:$E$58,Census!$G11+C$5-18)*IF((Census!$F11+C$5)>=Assumptions!$B$11,1,0))*MIN(15/26*Census!$D11*(1+Assumptions!$B$9)^C$5*(INT((Census!$F11+C$5))+IF((Census!$F11+C$5)-INT((Census!$F11+C$5))>0.5,1,0)),Assumptions!$B$10)) -> 25778.403 | D11: =IF(D$5>$B11,0,INDEX(Decrements!$G$6:$G$58,Census!$G11+D$5-18)/INDEX(Decrements!$G$6:$G$58,Census!$G11-17)*(INDEX(Decrements!$D$6:$D$58,Census!$G11+D$5-18)+IF(D$5=$B11,INDEX(Decrements!$F$6:$F$58,Census!$G11+D$5-18),0)+INDEX(Decrements!$E$6:$E$58,Census!$G11+D$5-18)*IF((Census!$F11+D$5)>=Assumptions!$B$11,1,0))*MIN(15/26*Census!$D11*(1+Assumptions!$B$9)^D$5*(INT((Census!$F11+D$5))+IF((Census!$F11+D$5)-INT((Census!$F11+D$5))>0.5,1,0)),Assumptions!$B$10)) -> 28165.955 | E11: =IF(E$5>$B11,0,INDEX(Decrements!$G$6:$G$58,Census!$G11+E$5-18)/INDEX(Decrements!$G$6:$G$58,Census!$G11-17)*(INDEX(Decrements!$D$6:$D$58,Census!$G11+E$5-18)+IF(E$5=$B11,INDEX(Decrements!$F$6:$F$58,Census!$G11+E$5-18),0)+INDEX(Decrements!$E$6:$E$58,Census!$G11+E$5-18)*IF((Census!$F11+E$5)>=Assumptions!$B$11,1,0))*MIN(15/26*Census!$D11*(1+Assumptions!$B$9)^E$5*(INT((Census!$F11+E$5))+IF((Census!$F11+E$5)-INT((Census!$F11+E$5))>0.5,1,0)),Assumptions!$B$10)) -> 30520.549 | F11: =IF(F$5>$B11,0,INDEX(Decrements!$G$6:$G$58,Census!$G11+F$5-18)/INDEX(Decrements!$G$6:$G$58,Census!$G11-17)*(INDEX(Decrements!$D$6:$D$58,Census!$G11+F$5-18)+IF(F$5=$B11,INDEX(Decrements!$F$6:$F$58,Census!$G11+F$5-18),0)+INDEX(Decrements!$E$6:$E$58,Census!$G11+F$5-18)*IF((Census!$F11+F$5)>=Assumptions!$B$11,1,0))*MIN(15/26*Census!$D11*(1+Assumptions!$B$9)^F$5*(INT((Census!$F11+F$5))+IF((Census!$F11+F$5)-INT((Census!$F11+F$5))>0.5,1,0)),Assumptions!$B$10)) -> 32842.6 | G11: =IF(G$5>$B11,0,INDEX(Decrements!$G$6:$G$58,Census!$G11+G$5-18)/INDEX(Decrements!$G$6:$G$58,Census!$G11-17)*(INDEX(Decrements!$D$6:$D$58,Census!$G11+G$5-18)+IF(G$5=$B11,INDEX(Decrements!$F$6:$F$58,Census!$G11+G$5-18),0)+INDEX(Decrements!$E$6:$E$58,Census!$G11+G$5-18)*IF((Census!$F11+G$5)>=Assumptions!$B$11,1,0))*MIN(15/26*Census!$D11*(1+Assumptions!$B$9)^G$5*(INT((Census!$F11+G$5))+IF((Census!$F11+G$5)-INT((Census!$F11+G$5))>0.5,1,0)),Assumptions!$B$10)) -> 22176.565 | H11: =IF(H$5>$B11,0,INDEX(Decrements!$G$6:$G$58,Census!$G11+H$5-18)/INDEX(Decrements!$G$6:$G$58,Census!$G11-17)*(INDEX(Decrements!$D$6:$D$58,Census!$G11+H$5-18)+IF(H$5=$B11,INDEX(Decrements!$F$6:$F$58,Census!$G11+H$5-18),0)+INDEX(Decrements!$E$6:$E$58,Census!$G11+H$5-18)*IF((Census!$F11+H$5)>=Assumptions!$B$11,1,0))*MIN(15/26*Census!$D11*(1+Assumptions!$B$9)^H$5*(INT((Census!$F11+H$5))+IF((Census!$F11+H$5)-INT((Census!$F11+H$5))>0.5,1,0)),Assumptions!$B$10)) -> 24388.272 | I11: =IF(I$5>$B11,0,INDEX(Decrements!$G$6:$G$58,Census!$G11+I$5-18)/INDEX(Decrements!$G$6:$G$58,Census!$G11-17)*(INDEX(Decrements!$D$6:$D$58,Census!$G11+I$5-18)+IF(I$5=$B11,INDEX(Decrements!$F$6:$F$58,Census!$G11+I$5-18),0)+INDEX(Decrements!$E$6:$E$58,Census!$G11+I$5-18)*IF((Census!$F11+I$5)>=Assumptions!$B$11,1,0))*MIN(15/26*Census!$D11*(1+Assumptions!$B$9)^I$5*(INT((Census!$F11+I$5))+IF((Census!$F11+I$5)-INT((Census!$F11+I$5))>0.5,1,0)),Assumptions!$B$10)) -> 26703.406 | J11: =IF(J$5>$B11,0,INDEX(Decrements!$G$6:$G$58,Census!$G11+J$5-18)/INDEX(Decrements!$G$6:$G$58,Census!$G11-17)*(INDEX(Decrements!$D$6:$D$58,Census!$G11+J$5-18)+IF(J$5=$B11,INDEX(Decrements!$F$6:$F$58,Census!$G11+J$5-18),0)+INDEX(Decrements!$E$6:$E$58,Census!$G11+J$5-18)*IF((Census!$F11+J$5)>=Assumptions!$B$11,1,0))*MIN(15/26*Census!$D11*(1+Assumptions!$B$9)^J$5*(INT((Census!$F11+J$5))+IF((Census!$F11+J$5)-INT((Census!$F11+J$5))>0.5,1,0)),Assumptions!$B$10)) -> 29126.538 | ... AU11: =IF(AU$5>$B11,0,INDEX(Decrements!$G$6:$G$58,Census!$G11+AU$5-18)/INDEX(Decrements!$G$6:$G$58,Census!$G11-17)*(INDEX(Decrements!$D$6:$D$58,Census!$G11+AU$5-18)+IF(AU$5=$B11,INDEX(Decrements!$F$6:$F$58,Census!$G11+AU$5-18),0)+INDEX(Decrements!$E$6:$E$58,Census!$G11+AU$5-18)*IF((Census!$F11+AU$5)>=Assumptions!$B$11,1,0))*MIN(15/26*Census!$D11*(1+Assumptions!$B$9)^AU$5*(INT((Census!$F11+AU$5))+IF((Census!$F11+AU$5)-INT((Census!$F11+AU$5))>0.5,1,0)),Assumptions!$B$10)) -> 0
A12: =Census!A12 -> E007 | B12: =Census!H12 -> 25 | C12: =IF(C$5>$B12,0,INDEX(Decrements!$G$6:$G$58,Census!$G12+C$5-18)/INDEX(Decrements!$G$6:$G$58,Census!$G12-17)*(INDEX(Decrements!$D$6:$D$58,Census!$G12+C$5-18)+IF(C$5=$B12,INDEX(Decrements!$F$6:$F$58,Census!$G12+C$5-18),0)+INDEX(Decrements!$E$6:$E$58,Census!$G12+C$5-18)*IF((Census!$F12+C$5)>=Assumptions!$B$11,1,0))*MIN(15/26*Census!$D12*(1+Assumptions!$B$9)^C$5*(INT((Census!$F12+C$5))+IF((Census!$F12+C$5)-INT((Census!$F12+C$5))>0.5,1,0)),Assumptions!$B$10)) -> 25105.775 | D12: =IF(D$5>$B12,0,INDEX(Decrements!$G$6:$G$58,Census!$G12+D$5-18)/INDEX(Decrements!$G$6:$G$58,Census!$G12-17)*(INDEX(Decrements!$D$6:$D$58,Census!$G12+D$5-18)+IF(D$5=$B12,INDEX(Decrements!$F$6:$F$58,Census!$G12+D$5-18),0)+INDEX(Decrements!$E$6:$E$58,Census!$G12+D$5-18)*IF((Census!$F12+D$5)>=Assumptions!$B$11,1,0))*MIN(15/26*Census!$D12*(1+Assumptions!$B$9)^D$5*(INT((Census!$F12+D$5))+IF((Census!$F12+D$5)-INT((Census!$F12+D$5))>0.5,1,0)),Assumptions!$B$10)) -> 27430.826 | E12: =IF(E$5>$B12,0,INDEX(Decrements!$G$6:$G$58,Census!$G12+E$5-18)/INDEX(Decrements!$G$6:$G$58,Census!$G12-17)*(INDEX(Decrements!$D$6:$D$58,Census!$G12+E$5-18)+IF(E$5=$B12,INDEX(Decrements!$F$6:$F$58,Census!$G12+E$5-18),0)+INDEX(Decrements!$E$6:$E$58,Census!$G12+E$5-18)*IF((Census!$F12+E$5)>=Assumptions!$B$11,1,0))*MIN(15/26*Census!$D12*(1+Assumptions!$B$9)^E$5*(INT((Census!$F12+E$5))+IF((Census!$F12+E$5)-INT((Census!$F12+E$5))>0.5,1,0)),Assumptions!$B$10)) -> 29723.726 | F12: =IF(F$5>$B12,0,INDEX(Decrements!$G$6:$G$58,Census!$G12+F$5-18)/INDEX(Decrements!$G$6:$G$58,Census!$G12-17)*(INDEX(Decrements!$D$6:$D$58,Census!$G12+F$5-18)+IF(F$5=$B12,INDEX(Decrements!$F$6:$F$58,Census!$G12+F$5-18),0)+INDEX(Decrements!$E$6:$E$58,Census!$G12+F$5-18)*IF((Census!$F12+F$5)>=Assumptions!$B$11,1,0))*MIN(15/26*Census!$D12*(1+Assumptions!$B$9)^F$5*(INT((Census!$F12+F$5))+IF((Census!$F12+F$5)-INT((Census!$F12+F$5))>0.5,1,0)),Assumptions!$B$10)) -> 31984.875 | G12: =IF(G$5>$B12,0,INDEX(Decrements!$G$6:$G$58,Census!$G12+G$5-18)/INDEX(Decrements!$G$6:$G$58,Census!$G12-17)*(INDEX(Decrements!$D$6:$D$58,Census!$G12+G$5-18)+IF(G$5=$B12,INDEX(Decrements!$F$6:$F$58,Census!$G12+G$5-18),0)+INDEX(Decrements!$E$6:$E$58,Census!$G12+G$5-18)*IF((Census!$F12+G$5)>=Assumptions!$B$11,1,0))*MIN(15/26*Census!$D12*(1+Assumptions!$B$9)^G$5*(INT((Census!$F12+G$5))+IF((Census!$F12+G$5)-INT((Census!$F12+G$5))>0.5,1,0)),Assumptions!$B$10)) -> 34214.675 | H12: =IF(H$5>$B12,0,INDEX(Decrements!$G$6:$G$58,Census!$G12+H$5-18)/INDEX(Decrements!$G$6:$G$58,Census!$G12-17)*(INDEX(Decrements!$D$6:$D$58,Census!$G12+H$5-18)+IF(H$5=$B12,INDEX(Decrements!$F$6:$F$58,Census!$G12+H$5-18),0)+INDEX(Decrements!$E$6:$E$58,Census!$G12+H$5-18)*IF((Census!$F12+H$5)>=Assumptions!$B$11,1,0))*MIN(15/26*Census!$D12*(1+Assumptions!$B$9)^H$5*(INT((Census!$F12+H$5))+IF((Census!$F12+H$5)-INT((Census!$F12+H$5))>0.5,1,0)),Assumptions!$B$10)) -> 22985.169 | I12: =IF(I$5>$B12,0,INDEX(Decrements!$G$6:$G$58,Census!$G12+I$5-18)/INDEX(Decrements!$G$6:$G$58,Census!$G12-17)*(INDEX(Decrements!$D$6:$D$58,Census!$G12+I$5-18)+IF(I$5=$B12,INDEX(Decrements!$F$6:$F$58,Census!$G12+I$5-18),0)+INDEX(Decrements!$E$6:$E$58,Census!$G12+I$5-18)*IF((Census!$F12+I$5)>=Assumptions!$B$11,1,0))*MIN(15/26*Census!$D12*(1+Assumptions!$B$9)^I$5*(INT((Census!$F12+I$5))+IF((Census!$F12+I$5)-INT((Census!$F12+I$5))>0.5,1,0)),Assumptions!$B$10)) -> 25165.175 | J12: =IF(J$5>$B12,0,INDEX(Decrements!$G$6:$G$58,Census!$G12+J$5-18)/INDEX(Decrements!$G$6:$G$58,Census!$G12-17)*(INDEX(Decrements!$D$6:$D$58,Census!$G12+J$5-18)+IF(J$5=$B12,INDEX(Decrements!$F$6:$F$58,Census!$G12+J$5-18),0)+INDEX(Decrements!$E$6:$E$58,Census!$G12+J$5-18)*IF((Census!$F12+J$5)>=Assumptions!$B$11,1,0))*MIN(15/26*Census!$D12*(1+Assumptions!$B$9)^J$5*(INT((Census!$F12+J$5))+IF((Census!$F12+J$5)-INT((Census!$F12+J$5))>0.5,1,0)),Assumptions!$B$10)) -> 27446.426 | ... AU12: =IF(AU$5>$B12,0,INDEX(Decrements!$G$6:$G$58,Census!$G12+AU$5-18)/INDEX(Decrements!$G$6:$G$58,Census!$G12-17)*(INDEX(Decrements!$D$6:$D$58,Census!$G12+AU$5-18)+IF(AU$5=$B12,INDEX(Decrements!$F$6:$F$58,Census!$G12+AU$5-18),0)+INDEX(Decrements!$E$6:$E$58,Census!$G12+AU$5-18)*IF((Census!$F12+AU$5)>=Assumptions!$B$11,1,0))*MIN(15/26*Census!$D12*(1+Assumptions!$B$9)^AU$5*(INT((Census!$F12+AU$5))+IF((Census!$F12+AU$5)-INT((Census!$F12+AU$5))>0.5,1,0)),Assumptions!$B$10)) -> 0
A13: =Census!A13 -> E008 | B13: =Census!H13 -> 25 | C13: =IF(C$5>$B13,0,INDEX(Decrements!$G$6:$G$58,Census!$G13+C$5-18)/INDEX(Decrements!$G$6:$G$58,Census!$G13-17)*(INDEX(Decrements!$D$6:$D$58,Census!$G13+C$5-18)+IF(C$5=$B13,INDEX(Decrements!$F$6:$F$58,Census!$G13+C$5-18),0)+INDEX(Decrements!$E$6:$E$58,Census!$G13+C$5-18)*IF((Census!$F13+C$5)>=Assumptions!$B$11,1,0))*MIN(15/26*Census!$D13*(1+Assumptions!$B$9)^C$5*(INT((Census!$F13+C$5))+IF((Census!$F13+C$5)-INT((Census!$F13+C$5))>0.5,1,0)),Assumptions!$B$10)) -> 25342.717 | D13: =IF(D$5>$B13,0,INDEX(Decrements!$G$6:$G$58,Census!$G13+D$5-18)/INDEX(Decrements!$G$6:$G$58,Census!$G13-17)*(INDEX(Decrements!$D$6:$D$58,Census!$G13+D$5-18)+IF(D$5=$B13,INDEX(Decrements!$F$6:$F$58,Census!$G13+D$5-18),0)+INDEX(Decrements!$E$6:$E$58,Census!$G13+D$5-18)*IF((Census!$F13+D$5)>=Assumptions!$B$11,1,0))*MIN(15/26*Census!$D13*(1+Assumptions!$B$9)^D$5*(INT((Census!$F13+D$5))+IF((Census!$F13+D$5)-INT((Census!$F13+D$5))>0.5,1,0)),Assumptions!$B$10)) -> 27460.871 | E13: =IF(E$5>$B13,0,INDEX(Decrements!$G$6:$G$58,Census!$G13+E$5-18)/INDEX(Decrements!$G$6:$G$58,Census!$G13-17)*(INDEX(Decrements!$D$6:$D$58,Census!$G13+E$5-18)+IF(E$5=$B13,INDEX(Decrements!$F$6:$F$58,Census!$G13+E$5-18),0)+INDEX(Decrements!$E$6:$E$58,Census!$G13+E$5-18)*IF((Census!$F13+E$5)>=Assumptions!$B$11,1,0))*MIN(15/26*Census!$D13*(1+Assumptions!$B$9)^E$5*(INT((Census!$F13+E$5))+IF((Census!$F13+E$5)-INT((Census!$F13+E$5))>0.5,1,0)),Assumptions!$B$10)) -> 29549.641 | F13: =IF(F$5>$B13,0,INDEX(Decrements!$G$6:$G$58,Census!$G13+F$5-18)/INDEX(Decrements!$G$6:$G$58,Census!$G13-17)*(INDEX(Decrements!$D$6:$D$58,Census!$G13+F$5-18)+IF(F$5=$B13,INDEX(Decrements!$F$6:$F$58,Census!$G13+F$5-18),0)+INDEX(Decrements!$E$6:$E$58,Census!$G13+F$5-18)*IF((Census!$F13+F$5)>=Assumptions!$B$11,1,0))*MIN(15/26*Census!$D13*(1+Assumptions!$B$9)^F$5*(INT((Census!$F13+F$5))+IF((Census!$F13+F$5)-INT((Census!$F13+F$5))>0.5,1,0)),Assumptions!$B$10)) -> 31609.396 | G13: =IF(G$5>$B13,0,INDEX(Decrements!$G$6:$G$58,Census!$G13+G$5-18)/INDEX(Decrements!$G$6:$G$58,Census!$G13-17)*(INDEX(Decrements!$D$6:$D$58,Census!$G13+G$5-18)+IF(G$5=$B13,INDEX(Decrements!$F$6:$F$58,Census!$G13+G$5-18),0)+INDEX(Decrements!$E$6:$E$58,Census!$G13+G$5-18)*IF((Census!$F13+G$5)>=Assumptions!$B$11,1,0))*MIN(15/26*Census!$D13*(1+Assumptions!$B$9)^G$5*(INT((Census!$F13+G$5))+IF((Census!$F13+G$5)-INT((Census!$F13+G$5))>0.5,1,0)),Assumptions!$B$10)) -> 33640.505 | H13: =IF(H$5>$B13,0,INDEX(Decrements!$G$6:$G$58,Census!$G13+H$5-18)/INDEX(Decrements!$G$6:$G$58,Census!$G13-17)*(INDEX(Decrements!$D$6:$D$58,Census!$G13+H$5-18)+IF(H$5=$B13,INDEX(Decrements!$F$6:$F$58,Census!$G13+H$5-18),0)+INDEX(Decrements!$E$6:$E$58,Census!$G13+H$5-18)*IF((Census!$F13+H$5)>=Assumptions!$B$11,1,0))*MIN(15/26*Census!$D13*(1+Assumptions!$B$9)^H$5*(INT((Census!$F13+H$5))+IF((Census!$F13+H$5)-INT((Census!$F13+H$5))>0.5,1,0)),Assumptions!$B$10)) -> 22499.003 | I13: =IF(I$5>$B13,0,INDEX(Decrements!$G$6:$G$58,Census!$G13+I$5-18)/INDEX(Decrements!$G$6:$G$58,Census!$G13-17)*(INDEX(Decrements!$D$6:$D$58,Census!$G13+I$5-18)+IF(I$5=$B13,INDEX(Decrements!$F$6:$F$58,Census!$G13+I$5-18),0)+INDEX(Decrements!$E$6:$E$58,Census!$G13+I$5-18)*IF((Census!$F13+I$5)>=Assumptions!$B$11,1,0))*MIN(15/26*Census!$D13*(1+Assumptions!$B$9)^I$5*(INT((Census!$F13+I$5))+IF((Census!$F13+I$5)-INT((Census!$F13+I$5))>0.5,1,0)),Assumptions!$B$10)) -> 24536.678 | J13: =IF(J$5>$B13,0,INDEX(Decrements!$G$6:$G$58,Census!$G13+J$5-18)/INDEX(Decrements!$G$6:$G$58,Census!$G13-17)*(INDEX(Decrements!$D$6:$D$58,Census!$G13+J$5-18)+IF(J$5=$B13,INDEX(Decrements!$F$6:$F$58,Census!$G13+J$5-18),0)+INDEX(Decrements!$E$6:$E$58,Census!$G13+J$5-18)*IF((Census!$F13+J$5)>=Assumptions!$B$11,1,0))*MIN(15/26*Census!$D13*(1+Assumptions!$B$9)^J$5*(INT((Census!$F13+J$5))+IF((Census!$F13+J$5)-INT((Census!$F13+J$5))>0.5,1,0)),Assumptions!$B$10)) -> 26668.356 | ... AU13: =IF(AU$5>$B13,0,INDEX(Decrements!$G$6:$G$58,Census!$G13+AU$5-18)/INDEX(Decrements!$G$6:$G$58,Census!$G13-17)*(INDEX(Decrements!$D$6:$D$58,Census!$G13+AU$5-18)+IF(AU$5=$B13,INDEX(Decrements!$F$6:$F$58,Census!$G13+AU$5-18),0)+INDEX(Decrements!$E$6:$E$58,Census!$G13+AU$5-18)*IF((Census!$F13+AU$5)>=Assumptions!$B$11,1,0))*MIN(15/26*Census!$D13*(1+Assumptions!$B$9)^AU$5*(INT((Census!$F13+AU$5))+IF((Census!$F13+AU$5)-INT((Census!$F13+AU$5))>0.5,1,0)),Assumptions!$B$10)) -> 0
